<?xml version="1.0" encoding="utf-8"?>

<robot name="rbq10v5">
    <material name="black">
        <color rgba="0.0 0.0 0.0 1.0" />
    </material>
    <material name="blue">
        <color rgba="0.0 0.0 0.8 1.0" />
    </material>
    <material name="green">
        <color rgba="0.0 0.8 0.0 1.0" />
    </material>
    <material name="grey">
        <color rgba="0.2 0.2 0.2 1.0" />
    </material>
    <material name="silver">
        <color rgba="0.913725490196 0.913725490196 0.847058823529 1.0" />
    </material>
    <material name="orange">
        <color rgba="1.0 0.423529411765 0.0392156862745 1.0" />
    </material>
    <material name="brown">
        <color rgba="0.870588235294 0.811764705882 0.764705882353 1.0" />
    </material>
    <material name="red">
        <color rgba="0.8 0.0 0.0 1.0" />
    </material>
    <material name="white">
        <color rgba="1.0 1.0 1.0 1.0" />
    </material>


    <link name="base">
        <visual>
            <origin rpy="0 0 0" xyz="0 0 0" />
            <geometry>
                <box size="0.001 0.001 0.001" />
            </geometry>
        </visual>
    </link>

    <joint name="floating_base" type="fixed">
        <origin rpy="0 0 0" xyz="0 0 0" />
        <parent link="base" />
        <child link="trunk" />
    </joint>

    <link name="trunk">

        <visual>
            <origin xyz="0 0 0" rpy="0 0 0" />
            <geometry>
                <mesh filename="package://rbq_description/meshes/stl/fuselage.stl"
                    scale="0.001 0.001 0.001" />
            </geometry>
            <material name="tan">
                <color rgba="0.823 0.706 0.549 1" />
            </material>
        </visual>

        <collision>
            <origin rpy="0 0 0" xyz="0 0 0" />
            <geometry>
                <box size="0.8002 0.0935 0.114" />
            </geometry>
        </collision>

        <inertial>
            <origin xyz="0.015 0.0 0.0" rpy="0 0 0" />
            <mass value="15.4" />
            <inertia
                ixx="0.0649"
                ixy="-0.000875" iyy="0.170145"
                ixz="0.000538" iyz="-0.000063" izz="0.221698" />
        </inertial>

    </link>

    <joint name="imu_joint" type="fixed">
        <parent link="trunk" />
        <child link="imu_link" />
        <origin rpy="0 0 0" xyz="-0.01592 -0.06659 -0.00617" />
    </joint>

    <link name="imu_link">
        <inertial>
            <mass value="0.001" />
            <origin rpy="0 0 0" xyz="0 0 0" />
            <inertia ixx="0.0001" ixy="0" ixz="0" iyy="0.0001" iyz="0" izz="0.0001" />
        </inertial>

        <visual>
            <origin rpy="0 0 0" xyz="0 0 0" />
            <geometry>
                <box size="0.001 0.001 0.001" />
            </geometry>
            <material name="red" />
        </visual>

    </link>

    <link name="RR">

        <visual>
            <origin xyz="0 0 0" rpy="0 0 3.1416" />
            <geometry>
                <mesh filename="package://rbq_description/meshes/stl/leg3.stl"
                    scale="0.001 0.001 0.001" />
            </geometry>
            <material name="">
                <color
                    rgba="0.2 0.2 0.2 1" />
            </material>
        </visual>

    </link>

    <link name="RR_hip">

        <inertial>
            <origin xyz="-0.02 0.0 0.0" rpy="0 0 0" />
            <mass value="3.2" />
            <inertia
                ixx="0.0050"
                ixy="0.0" iyy="0.001688"
                ixz="0.0" iyz="0.0" izz="0.003536" />
        </inertial>

        <visual>
            <origin xyz="0 0 0" rpy="0 0 3.1416" />
            <geometry>
                <mesh filename="package://rbq_description/meshes/stl/hip3.stl"
                    scale="0.001 0.001 0.001" />
            </geometry>
            <material name="palegoldenrog">
                <color rgba="0.9334 0.91 0.667 1.0" />
            </material>
        </visual>

    </link>

    <link name="RR_thigh">

        <inertial>
            <origin xyz="0.0 0.0 -0.04" rpy="0 0 0" />
            <mass value="2.0" />
            <inertia
                ixx="0.005338"
                ixy="0.000036" iyy="0.005691"
                ixz="0.000376" iyz="0.000322" izz="0.000814" />
        </inertial>

        <visual>
            <origin xyz="0 0 0" rpy="0 0 0" />
            <geometry>
                <mesh filename="package://rbq_description/meshes/stl/thigh_right.stl"
                    scale="0.001 0.001 0.001" />
            </geometry>
            <material name="">
                <color
                    rgba="0.75294 0.75294 0.75294 1" />
            </material>
        </visual>

        <collision>
            <origin rpy="1.57 0 0" xyz="0 0 0" />
            <geometry>
                <cylinder radius="0.05" length="0.03" />
            </geometry>
        </collision>

        <collision>
            <origin rpy="0 0 0" xyz="0 0 -0.15" />
            <geometry>
                <box size="0.05 0.04 0.2" />
            </geometry>
        </collision>

    </link>

    <link name="RR_calf">

        <visual>
            <origin xyz="0 0 0" rpy="0 0 0" />
            <geometry>
                <mesh filename="package://rbq_description/meshes/stl/calf.stl"
                    scale="0.001 0.001 0.001" />
            </geometry>
            <material name="">
                <color rgba="0.3 0.3 0.3 1" />
            </material>
        </visual>

        <collision>
            <origin rpy="0 0 0" xyz="0.15 0 0" />
            <geometry>
                <box size="0.2 0.02 0.03" />
            </geometry>
        </collision>

        <inertial>
            <origin rpy="0 0 0" xyz="0.006286 0.001307 -0.122269" />
            <mass value="0.158015" />
            <inertia ixx="0.003607648222" ixy="1.494971e-06" ixz="-0.000132778525"
                iyy="0.003626771492" iyz="-2.8638535e-05" izz="3.5148003e-05" />
        </inertial>

    </link>

    <link name="RR_foot">
        <inertial>
            <mass value="0.06" />
            <inertia ixx="9.6e-06" ixy="0.0" ixz="0.0" iyy="9.6e-06" iyz="0.0" izz="9.6e-06" />
        </inertial>

        <collision>
            <origin xyz="0 0 0" rpy="0 0 0" />
            <geometry>
                <sphere radius="0.034" />
            </geometry>
        </collision>

        <visual>
            <origin xyz="0 0 0" rpy="0 0 0" />
            <geometry>
                <mesh filename="package://rbq_description/meshes/stl/foot.stl" 
                    scale="0.001 0.001 0.001" />
            </geometry>
            <material name="">
                <color rgba="0.3 0.3 0.3 1" />
            </material>
        </visual>
    </link>

    <joint name="RR_joint" type="fixed">
        <origin xyz="-0.19725 -0.09 0" rpy="0 0 0" />
        <parent link="trunk" />
        <child link="RR" />
        <axis xyz="0 0 0" />
    </joint>

    <joint name="RR_hip_joint" type="revolute">
        <origin
            xyz="-0.11493 0 0"
            rpy="0 0 0" />
        <parent
            link="RR" />
        <child
            link="RR_hip" />
        <axis
            xyz="1 0 0" />
        <limit
            effort="80.0" velocity="20."
            lower="-0.524"
            upper="0.524" />
        <dynamics
            damping="0.0"
            friction="0.0" />
    </joint>

    <joint name="RR_thigh_joint" type="revolute">
        <origin
            xyz="0 -0.10285 0"
            rpy="0 0 0" />
        <parent
            link="RR_hip" />
        <child
            link="RR_thigh" />
        <axis
            xyz="0 1 0" />
        <limit
            effort="80.0" velocity="20."
            lower="-1.0471975512"
            upper="4.18879020479" />
    </joint>

    <joint name="RR_calf_joint" type="revolute">
        <origin
            xyz="0 0 -0.3"
            rpy="0 1.57 0" />
        <parent
            link="RR_thigh" />
        <child
            link="RR_calf" />
        <axis
            xyz="0 1 0" />
        <limit
            effort="80.0" velocity="20."
            lower="-2.76"
            upper="-0.46" />
        <dynamics
            damping="0.0"
            friction="0.0" />
    </joint>

    <joint name="RR_foot_joint" type="fixed">
        <origin
            xyz="0.294 0 0"
            rpy="0 0 0" />
        <parent
            link="RR_calf" />
        <child
            link="RR_foot" />
        <axis
            xyz="0 0 0" />
    </joint>


    <link name="RL">

        <visual>
            <origin xyz="0 0 0" rpy="3.1416 0 3.1416" />
            <geometry>
                <mesh filename="package://rbq_description/meshes/stl/leg3.stl"
                    scale="0.001 0.001 0.001" />
            </geometry>
            <material name="">
                <color
                    rgba="0.2 0.2 0.2 1" />
            </material>
        </visual>

    </link>

    <link name="RL_hip">

        <inertial>
            <origin xyz="-0.02 0.0 0.0" rpy="0 0 0" />
            <mass value="3.2" />
            <inertia
                ixx="0.0050"
                ixy="0.0" iyy="0.001688"
                ixz="0.0" iyz="0.0" izz="0.003536" />
        </inertial>

        <visual>
            <origin xyz="0 0 0" rpy="0 0 0" />
            <geometry>
                <mesh filename="package://rbq_description/meshes/stl/hip1.stl"
                    scale="0.001 0.001 0.001" />
            </geometry>
            <material name="palegoldenrog">
                <color rgba="0.9334 0.91 0.667 1.0" />
            </material>
        </visual>

    </link>

    <link name="RL_thigh">

        <inertial>
            <origin xyz="0.0 0.0 -0.04" rpy="0 0 0" />
            <mass value="2.0" />
            <inertia
                ixx="0.005338"
                ixy="0.000036" iyy="0.005691"
                ixz="0.000376" iyz="0.000322" izz="0.000814" />
        </inertial>

        <visual>
            <origin xyz="0 0 0" rpy="0 0 0" />
            <geometry>
                <mesh filename="package://rbq_description/meshes/stl/thigh_left.stl"
                    scale="0.001 0.001 0.001" />
            </geometry>
            <material name="">
                <color
                    rgba="0.75294 0.75294 0.75294 1" />
            </material>
        </visual>

        <collision>
            <origin rpy="1.57 0 0" xyz="0 0 0" />
            <geometry>
                <cylinder radius="0.05" length="0.03" />
            </geometry>
        </collision>

        <collision>
            <origin rpy="0 0 0" xyz="0 0 -0.15" />
            <geometry>
                <box size="0.05 0.04 0.2" />
            </geometry>
        </collision>

    </link>

    <link name="RL_calf">

        <visual>
            <origin xyz="0 0 0" rpy="0 0 0" />
            <geometry>
                <mesh filename="package://rbq_description/meshes/stl/calf.stl"
                    scale="0.001 0.001 0.001" />
            </geometry>
            <material name="">
                <color rgba="0.3 0.3 0.3 1" />
            </material>
        </visual>

        <collision>
            <origin rpy="0 0 0" xyz="0.15 0 0" />
            <geometry>
                <box size="0.2 0.02 0.03" />
            </geometry>
        </collision>

        <inertial>
            <origin rpy="0 0 0" xyz="0.006286 0.001307 -0.122269" />
            <mass value="0.158015" />
            <inertia ixx="0.003607648222" ixy="1.494971e-06" ixz="-0.000132778525"
                iyy="0.003626771492" iyz="-2.8638535e-05" izz="3.5148003e-05" />
        </inertial>

    </link>

    <link name="RL_foot">
        <inertial>
            <mass value="0.06" />
            <inertia ixx="9.6e-06" ixy="0.0" ixz="0.0" iyy="9.6e-06" iyz="0.0" izz="9.6e-06" />
        </inertial>

        <collision>
            <origin xyz="0 0 0" rpy="0 0 0" />
            <geometry>
                <sphere radius="0.034" />
            </geometry>
        </collision>

        <visual>
            <origin xyz="0 0 0" rpy="0 0 0" />
            <geometry>
                <mesh filename="package://rbq_description/meshes/stl/foot.stl" 
                    scale="0.001 0.001 0.001" />
            </geometry>
            <material name="">
                <color rgba="0.3 0.3 0.3 1" />
            </material>
        </visual>
    </link>


    <joint name="RL_joint" type="fixed">
        <origin
            xyz="-0.19725 0.09 0"
            rpy="0 0 0" />
        <parent
            link="trunk" />
        <child
            link="RL" />
        <axis
            xyz="0 0 0" />
    </joint>

    <joint name="RL_hip_joint" type="revolute">
        <origin
            xyz="-0.11493 0 0"
            rpy="0 0 0" />
        <parent
            link="RL" />
        <child
            link="RL_hip" />
        <axis
            xyz="1 0 0" />
        <limit
            effort="80.0" velocity="20."
            lower="-0.524"
            upper="0.524" />
        <dynamics
            damping="0.0"
            friction="0.0" />
    </joint>

    <joint name="RL_thigh_joint" type="revolute">
        <origin
            xyz="0 0.10285 0"
            rpy="0 0 0" />
        <parent
            link="RL_hip" />
        <child
            link="RL_thigh" />
        <axis
            xyz="0 1 0" />
        <limit
            effort="80.0" velocity="20."
            lower="-1.0471975512"
            upper="4.18879020479" />
    </joint>

    <joint name="RL_calf_joint" type="revolute">
        <origin
            xyz="0 0 -0.3"
            rpy="0 1.57 0" />
        <parent
            link="RL_thigh" />
        <child
            link="RL_calf" />
        <axis
            xyz="0 1 0" />
        <limit
            effort="80.0" velocity="20."
            lower="-2.76"
            upper="-0.46" />
        <dynamics
            damping="0.0"
            friction="0.0" />
    </joint>

    <joint name="RL_foot_joint" type="fixed">
        <origin
            xyz="0.294 0 0"
            rpy="0 0 0" />
        <parent
            link="RL_calf" />
        <child
            link="RL_foot" />
        <axis
            xyz="0 0 0" />
    </joint>


    <link name="FR">
        <inertial>
            <origin xyz="-2.7886E-05 -0.00038376 9.5274E-06" rpy="0 0 0" />
            <mass value="0.091477" />
            <inertia
                ixx="0.00012129" ixy="-4.0174E-09" ixz="1.2377E-09"
                iyy="6.3759E-05" iyz="-3.8932E-10"
                izz="6.0224E-05" />
        </inertial>
        <visual>
            <origin xyz="0 0 0" rpy="3.1416 0 0" />
            <geometry>
                <mesh filename="package://rbq_description/meshes/stl/leg3.stl"
                    scale="0.001 0.001 0.001" />
            </geometry>
            <material name="">
                <color rgba="0.2 0.2 0.2 1" />
            </material>
        </visual>
    </link>

    <link name="FR_hip">

        <inertial>
            <origin xyz="-0.02 0.0 0.0" rpy="0 0 0" />
            <mass value="3.2" />
            <inertia
                ixx="0.0050"
                ixy="0.0" iyy="0.001688"
                ixz="0.0" iyz="0.0" izz="0.003536" />
        </inertial>

        <visual>
            <origin xyz="0 0 0" rpy="0 0 3.1416" />
            <geometry>
                <mesh filename="package://rbq_description/meshes/stl/hip1.stl"
                    scale="0.001 0.001 0.001" />
            </geometry>
            <material name="palegoldenrog">
                <color rgba="0.9334 0.91 0.667 1.0" />
            </material>
        </visual>

    </link>

    <link name="FR_thigh">

        <inertial>
            <origin xyz="0.0 0.0 -0.04" rpy="0 0 0" />
            <mass value="2.0" />
            <inertia
                ixx="0.005338"
                ixy="0.000036" iyy="0.005691"
                ixz="0.000376" iyz="0.000322" izz="0.000814" />
        </inertial>

        <visual>
            <origin xyz="0 0 0" rpy="0 0 0" />
            <geometry>
                <mesh filename="package://rbq_description/meshes/stl/thigh_right.stl"
                    scale="0.001 0.001 0.001" />
            </geometry>
            <material name="">
                <color
                    rgba="0.75294 0.75294 0.75294 1" />
            </material>
        </visual>

        <collision>
            <origin rpy="1.57 0 0" xyz="0 0 0" />
            <geometry>
                <cylinder radius="0.05" length="0.03" />
            </geometry>
        </collision>

        <collision>
            <origin rpy="0 0 0" xyz="0 0 -0.15" />
            <geometry>
                <box size="0.05 0.04 0.2" />
            </geometry>
        </collision>

    </link>

    <link name="FR_calf">

        <visual>
            <origin xyz="0 0 0" rpy="0 0 0" />
            <geometry>
                <mesh filename="package://rbq_description/meshes/stl/calf.stl"
                    scale="0.001 0.001 0.001" />
            </geometry>
            <material name="">
                <color rgba="0.3 0.3 0.3 1" />
            </material>
        </visual>

        <collision>
            <origin rpy="0 0 0" xyz="0.15 0 0" />
            <geometry>
                <box size="0.2 0.02 0.03" />
            </geometry>
        </collision>

        <inertial>
            <origin rpy="0 0 0" xyz="0.006286 0.001307 -0.122269" />
            <mass value="0.158015" />
            <inertia ixx="0.003607648222" ixy="1.494971e-06" ixz="-0.000132778525"
                iyy="0.003626771492" iyz="-2.8638535e-05" izz="3.5148003e-05" />
        </inertial>

    </link>

    <link name="FR_foot">
        <inertial>
            <mass value="0.06" />
            <inertia ixx="9.6e-06" ixy="0.0" ixz="0.0" iyy="9.6e-06" iyz="0.0" izz="9.6e-06" />
        </inertial>

        <collision>
            <origin xyz="0 0 0" rpy="0 0 0" />
            <geometry>
                <sphere radius="0.034" />
            </geometry>
        </collision>

        <visual>
            <origin xyz="0 0 0" rpy="0 0 0" />
            <geometry>
                <mesh filename="package://rbq_description/meshes/stl/foot.stl" 
                    scale="0.001 0.001 0.001" />
            </geometry>
            <material name="">
                <color rgba="0.3 0.3 0.3 1" />
            </material>
        </visual>
    </link>


    <joint name="FR_joint" type="fixed">
        <origin
            xyz="0.19725 -0.09 0"
            rpy="0 0 0" />
        <parent
            link="trunk" />
        <child
            link="FR" />
        <axis
            xyz="0 0 0" />
    </joint>

    <joint name="FR_hip_joint" type="revolute">
        <origin
            xyz="0.11493 0 0"
            rpy="0 0 0" />
        <parent
            link="FR" />
        <child
            link="FR_hip" />
        <axis
            xyz="1 0 0" />
        <limit
            effort="80.0" velocity="20."
            lower="-0.524"
            upper="0.524" />
        <dynamics
            damping="0.0"
            friction="0.0" />
    </joint>

    <joint name="FR_thigh_joint" type="revolute">
        <origin
            xyz="0 -0.10285 0"
            rpy="0 0 0" />
        <parent
            link="FR_hip" />
        <child
            link="FR_thigh" />
        <axis
            xyz="0 1 0" />
        <limit
            effort="80.0" velocity="20."
            lower="-1.0471975512"
            upper="4.18879020479" />
    </joint>

    <joint name="FR_calf_joint" type="revolute">
        <origin
            xyz="0 0 -0.3"
            rpy="0 1.57 0" />
        <parent
            link="FR_thigh" />
        <child
            link="FR_calf" />
        <axis
            xyz="0 1 0" />
        <limit
            effort="80.0" velocity="20."
            lower="-2.76"
            upper="-0.46" />
        <dynamics
            damping="0.0"
            friction="0.0" />
    </joint>

    <joint name="FR_foot_joint" type="fixed">
        <origin
            xyz="0.294 0 0"
            rpy="0 0 0" />
        <parent
            link="FR_calf" />
        <child
            link="FR_foot" />
        <axis
            xyz="0 0 0" />
    </joint>


    <link name="FL">

        <visual>
            <origin xyz="0 0 0" rpy="0 0 0" />
            <geometry>
                <mesh filename="package://rbq_description/meshes/stl/leg3.stl"
                    scale="0.001 0.001 0.001" />
            </geometry>
            <material name="">
                <color
                    rgba="0.2 0.2 0.2 1" />
            </material>
        </visual>

    </link>

    <link name="FL_hip">

        <inertial>
            <origin xyz="-0.02 0.0 0.0" rpy="0 0 0" />
            <mass value="3.2" />
            <inertia
                ixx="0.0050"
                ixy="0.0" iyy="0.001688"
                ixz="0.0" iyz="0.0" izz="0.003536" />
        </inertial>

        <visual>
            <origin xyz="0 0 0" rpy="0 0 0" />
            <geometry>
                <mesh filename="package://rbq_description/meshes/stl/hip3.stl"
                    scale="0.001 0.001 0.001" />
            </geometry>
            <material name="palegoldenrog">
                <color rgba="0.9334 0.91 0.667 1.0" />
            </material>
        </visual>
    </link>

    <link name="FL_thigh">

        <inertial>
            <origin xyz="0.0 0.0 -0.04" rpy="0 0 0" />
            <mass value="2.0" />
            <inertia
                ixx="0.005338"
                ixy="0.000036" iyy="0.005691"
                ixz="0.000376" iyz="0.000322" izz="0.000814" />
        </inertial>

        <visual>
            <origin xyz="0 0 0" rpy="0 0 0" />
            <geometry>
                <mesh filename="package://rbq_description/meshes/stl/thigh_left.stl"
                    scale="0.001 0.001 0.001" />
            </geometry>
            <material name="">
                <color
                    rgba="0.75294 0.75294 0.75294 1" />
            </material>
        </visual>

        <collision>
            <origin rpy="1.57 0 0" xyz="0 0 0" />
            <geometry>
                <cylinder radius="0.05" length="0.03" />
            </geometry>
        </collision>

        <collision>
            <origin rpy="0 0 0" xyz="0 0 -0.15" />
            <geometry>
                <box size="0.05 0.04 0.2" />
            </geometry>
        </collision>

    </link>

    <link name="FL_calf">

        <visual>
            <origin xyz="0 0 0" rpy="0 0 0" />
            <geometry>
                <mesh filename="package://rbq_description/meshes/stl/calf.stl"
                    scale="0.001 0.001 0.001" />
            </geometry>
            <material name="">
                <color rgba="0.3 0.3 0.3 1" />
            </material>
        </visual>

        <collision>
            <origin rpy="0 0 0" xyz="0.15 0 0" />
            <geometry>
                <box size="0.2 0.02 0.03" />
            </geometry>
        </collision>

        <inertial>
            <origin rpy="0 0 0" xyz="0.006286 0.001307 -0.122269" />
            <mass value="0.158015" />
            <inertia ixx="0.003607648222" ixy="1.494971e-06" ixz="-0.000132778525"
                iyy="0.003626771492" iyz="-2.8638535e-05" izz="3.5148003e-05" />
        </inertial>

    </link>

    <link name="FL_foot">
        <inertial>
            <mass value="0.06" />
            <inertia ixx="9.6e-06" ixy="0.0" ixz="0.0" iyy="9.6e-06" iyz="0.0" izz="9.6e-06" />
        </inertial>

        <collision>
            <origin xyz="0 0 0" rpy="0 0 0" />
            <geometry>
                <sphere radius="0.034" />
            </geometry>
        </collision>

        <visual>
            <origin xyz="0 0 0" rpy="0 0 0" />
            <geometry>
                <mesh filename="package://rbq_description/meshes/stl/foot.stl" 
                    scale="0.001 0.001 0.001" />
            </geometry>
            <material name="">
                <color rgba="0.3 0.3 0.3 1" />
            </material>
        </visual>
    </link>


    <joint name="FL_joint" type="fixed">
        <origin
            xyz="0.19725 0.09 0"
            rpy="0 0 0" />
        <parent
            link="trunk" />
        <child
            link="FL" />
        <axis
            xyz="0 0 0" />
    </joint>

    <joint name="FL_hip_joint" type="revolute">
        <origin
            xyz="0.11493 0 0"
            rpy="0 0 0" />
        <parent
            link="FL" />
        <child
            link="FL_hip" />
        <axis
            xyz="1 0 0" />
        <limit
            effort="80.0" velocity="20."
            lower="-0.524"
            upper="0.524" />
        <dynamics
            damping="0.0"
            friction="0.0" />
    </joint>

    <joint name="FL_thigh_joint" type="revolute">
        <origin
            xyz="0 0.10285 0"
            rpy="0 0 0" />
        <parent
            link="FL_hip" />
        <child
            link="FL_thigh" />
        <axis
            xyz="0 1 0" />
        <dynamics damping="0" friction="0" />
        <limit
            effort="80.0" velocity="20."
            lower="-1.0471975512"
            upper="4.18879020479" />
    </joint>

    <joint name="FL_calf_joint" type="revolute">
        <origin
            xyz="0 0 -0.3"
            rpy="0 1.57 0" />
        <axis xyz="0 1 0" />
        <parent
            link="FL_thigh" />
        <child
            link="FL_calf" />
        <limit
            effort="80.0" velocity="20."
            lower="-2.76"
            upper="-0.46" />
        <dynamics
            damping="0.0"
            friction="0.0" />
    </joint>

    <joint name="FL_foot_joint" type="fixed">
        <origin
            xyz="0.294 0 0"
            rpy="0 0 0" />
        <parent
            link="FL_calf" />
        <child
            link="FL_foot" />
        <axis
            xyz="0 0 0" />
    </joint>

</robot>